/usr/lib/python3/dist-packages/requests/__init__.py:91: RequestsDependencyWarning: urllib3 (1.26.12) or chardet (3.0.4) doesn't match a supported version!
  RequestsDependencyWarning)
Traceback (most recent call last):
  File "/usr/lib/python3.7/configparser.py", line 845, in items
    d.update(self._sections[section])
KeyError: 'events'

During handling of the above exception, another exception occurred:

Traceback (most recent call last):
  File "/opt/seiscomp/share/sceewv/index.py", line 22, in <module>
    import events_dash
  File "/opt/seiscomp/share/sceewv/events_dash.py", line 44, in <module>
    cfg = dict(config.items('events'))
  File "/usr/lib/python3.7/configparser.py", line 848, in items
    raise NoSectionError(section)
configparser.NoSectionError: No section: 'events'
malloc_consolidate(): invalid chunk size
